Workbook

Sheet Overview
A1: BharatGen Speech Translation Intern Plan (8 weeks)
A3: Project Setup
A4: Intern name | B4: <fill in>
A5: Mentor name | B5: <fill in>
A6: Start date (Week 0 Day 1) | B6: <YYYY-MM-DD>
A7: End date (computed) | B7: =IF(ISNUMBER(B6),B6+55,"set start date")
A8: Repo URL | B8: <fill in>
A9: GPU environment | B9: RunPod (RTX 4090 or A40, persistent volume)
A10: HF token configured? | B10: No
A12: End state
A13: Working STT → Translate → TTS demo using BharatGen Shrutam-2 + AI4Bharat IndicTrans2 + BharatGen Sooktam-2, with a handoff package that lets the next intern start at Week 6, not Week 0. Week 0 is a 5-day Python+ML bootstrap; Weeks 1–7 are the working project.
A16: Status summary (auto)
A17: Total items | B17: 98
A18: Done | B18: 29
A19: In Progress | B19: 0
A20: Blocked | B20: 0
A21: Not Started | B21: 69
A22: % Complete | B22: 0.29591837

Sheet Tracker
A1: Week | B1: Week Start | C1: Section | D1: Item | E1: Description | F1: Rationale (why this is here) | G1: Owner | H1: Status | I1: Evidence / Link | J1: Notes
A2: Week 0 | B2: =IF(ISNUMBER(Overview!B6),Overview!B6+0,"") | C2: Setup | D2: HF account + accept gating | E2: Create HF account; accept terms on bharatgenai/Shrutam-2, bharatgenai/sooktam2, ai4bharat/indictrans2-indic-en-1B and en-indic-1B. Generate access token; set HF_TOKEN env var. Async, before Day 1. | F2: All three target models are gated or trust_remote_code. Token must be live before Day 1 or first model load fails. | G2: Intern | H2: Done
A3: Week 0 | B3: =IF(ISNUMBER(Overview!B6),Overview!B6+0,"") | C3: Setup | D3: RunPod pod + persistent volume | E3: Create RunPod account. Spin up a Pod with persistent volume attached (recommend 80-100 GB to fit HF cache for all 3 models + datasets). GPU template: RTX 4090 (24 GB, cheaper) or A40 (48 GB, headroom for Week 6 multi-model). Note: pod ID, volume ID, GPU type chosen — documented in repo README. | F3: Inference benchmarks are meaningful only against a fixed environment. Pod + GPU template should not change across weeks. Persistent volume so models survive pod restarts (otherwise re-downloading IndicTrans2-1B + Shrutam-2 + Sooktam-2 every cold start wastes 30+ min). | G3: Mentor | H3: Done | J3: Account created, pod will be created when required since it consumes credits
A4: Week 0 | B4: =IF(ISNUMBER(Overview!B6),Overview!B6+0,"") | C4: Setup | D4: HF cache on persistent volume | E4: On the Pod: `export HF_HOME=/workspace/.cache/huggingface` (or whatever the mount path is). Add to ~/.bashrc. Verify by loading a tiny model and checking the file lands on the persistent volume. | F4: Default HF cache lives in container ephemeral storage — wiped on pod restart. Pointing HF_HOME at the volume means model downloads are one-time. This single line saves ~5 hours over the internship. | G4: Intern | H4: Not Started
A5: Week 0 | B5: =IF(ISNUMBER(Overview!B6),Overview!B6+0,"") | C5: Setup | D5: Repo created | E5: Create `bharatgen-speech-intern-2026` with week0/ through week7/ folders. Branch protection so reviews are mandatory. | F5: Weekly commits make progress visible asynchronously. Removes the 'I lost my notebook' failure mode. | G5: Mentor | H5: Done
A6: Week 0 | B6: =IF(ISNUMBER(Overview!B6),Overview!B6+0,"") | C6: Setup | D6: Tooling installed | E6: Python 3.10, conda or uv, VS Code with Python + Jupyter extensions, ffmpeg, jupyter lab. | F6: ffmpeg is a hidden dependency for librosa/torchaudio/soundfile. Installing on Day 0 avoids a Day-1 audio-loading bug that looks unrelated. | G6: Intern | H6: Done
A7: Week 0 | B7: =IF(ISNUMBER(Overview!B6),Overview!B6+0,"") | C7: Setup | D7: Pre-reading (<=3 hours) | E7: AI4Bharat blog post on IndicTTS/IndicASR. Skim Shrutam-2 + Sooktam-2 model cards. No notes required. | F7: Builds vocabulary exposure so Day 3 concepts have anchor points. Retention is not the goal here. | G7: Intern | H7: Done | J7: Mark Done at end of Week 0 — vocabulary surfaces correctly in reflection.md (attention, transformers)
A8: Week 0 | B8: =IF(ISNUMBER(Overview!B6),Overview!B6+0,"") | C8: Concept | D8: Day 1: numpy - arrays, shape, dtype, broadcasting | E8: How arrays differ from Python lists. What .shape and .dtype mean. Broadcasting rules: when do (3,1) and (1,4) combine to (3,4). | F8: PyTorch tensors are numpy arrays + GPU + autograd. Master numpy first; PyTorch then feels 30% new, not 100% new. | G8: Intern | H8: Done
A9: Week 0 | B9: =IF(ISNUMBER(Overview!B6),Overview!B6+0,"") | C9: Concept | D9: Day 1: Jupyter cells, kernels, magics | E9: Cell execution order, kernel state, %time, %matplotlib inline. Why notebooks for exploration, scripts for production. | F9: ML work lives in notebooks. Notebook mental model is different from script mental model — hidden kernel state causes 'works for me' bugs. | G9: Intern | H9: Done
A10: Week 0 | B10: =IF(ISNUMBER(Overview!B6),Overview!B6+0,"") | C10: Hands-on | D10: Day 1: numpy exercises | E10: Create arrays, slice, broadcast, dot product, reshape. 10 small exercises. Write down what .shape will be BEFORE running each cell. | F10: Predicting shape before running is the discipline that prevents 80% of 'shape mismatch' bugs later. | G10: Intern | H10: Done
A11: Week 0 | B11: =IF(ISNUMBER(Overview!B6),Overview!B6+0,"") | C11: Hands-on | D11: Day 1: venv + requirements.txt comfort | E11: Create a fresh venv with uv or conda, install numpy/matplotlib/jupyter, freeze a requirements.txt. | F11: Every later week installs more packages. Environment hygiene now prevents 'it worked yesterday' problems in Week 4. | G11: Intern | H11: Done
A12: Week 0 | B12: =IF(ISNUMBER(Overview!B6),Overview!B6+0,"") | C12: Concept | D12: Day 2: matplotlib pyplot basics | E12: fig, ax = plt.subplots(). plot(), scatter(), hist(), set_xlabel/set_ylabel/set_title. | F12: Every week involves plotting something. Familiarity removes a recurring friction point. | G12: Intern | H12: Done
A13: Week 0 | B13: =IF(ISNUMBER(Overview!B6),Overview!B6+0,"") | C13: Hands-on | D13: Day 2: three plot types | E13: Plot a sine wave, a 1000-sample Gaussian histogram, a scatter of two correlated variables. Each plot labeled. | F13: Three plot types cover ~80% of what he'll plot. Practiced once, available always. | G13: Intern | H13: Done
A14: Week 0 | B14: =IF(ISNUMBER(Overview!B6),Overview!B6+0,"") | C14: Hands-on | D14: Day 2: read one library doc page end-to-end | E14: librosa 'Core IO and DSP' page. Read every section. Try one example from each. | F14: Reading docs is THE skill. Practicing it on a library he'll use next week is dual-purpose. | G14: Intern | H14: Done
A15: Week 0 | B15: =IF(ISNUMBER(Overview!B6),Overview!B6+0,"") | C15: Concept | D15: Day 3: what is a 'model' in ML | E15: A function with learned parameters. Input -> some math -> output. That's it for now. We won't train any — only run pre-trained ones. | F15: Demystifies the word. Removes the 'how does it learn' anxiety which is not Week 0's problem. | G15: Intern | H15: Done
A16: Week 0 | B16: =IF(ISNUMBER(Overview!B6),Overview!B6+0,"") | C16: Concept | D16: Day 3: what is a tensor (vs numpy array) | E16: Same data structure (n-dim array of numbers), but: lives on GPU, tracks gradients (we won't use this in inference). For our purposes: numpy array on a graphics card. | F16: 90% of 'PyTorch feels hard' is this conceptual confusion. Naming and dismissing it early saves a week. | G16: Intern | H16: Done
A17: Week 0 | B17: =IF(ISNUMBER(Overview!B6),Overview!B6+0,"") | C17: Concept | D17: Day 3: what is a tokenizer | E17: Converts text -> list of integers (tokens) so models can process it. Different models have different tokenizers. 'नमस्ते' might be 1 token or 5 tokens depending on the tokenizer. | F17: Crucial framing for Weeks 2-5 where tokenizers appear repeatedly. One-paragraph mental model is enough. | G17: Intern | H17: Done
A18: Week 0 | B18: =IF(ISNUMBER(Overview!B6),Overview!B6+0,"") | C18: Concept | D18: Day 3: training vs inference | E18: Training: model learns from labeled data. Inference: model runs on new inputs. We do inference only for 7 weeks. Knowing what we're NOT doing scopes the work. | F18: Bounds the scope explicitly. Pre-empts the 'should I train it' instinct that derails most first ML projects. | G18: Intern | H18: Done
A19: Week 0 | B19: =IF(ISNUMBER(Overview!B6),Overview!B6+0,"") | C19: Concept | D19: Day 3: GPU vs CPU intuition | E19: GPU = thousands of small parallel cores, great at matrix multiplications. CPU = few fast sequential cores. Neural network = millions of matmuls -> GPU is 10-100x faster. | F19: Frames Day 5's GPU warm-up and every subsequent profiling discussion. Intuition first, mechanics later. | G19: Intern | H19: Done
A20: Week 0 | B20: =IF(ISNUMBER(Overview!B6),Overview!B6+0,"") | C20: Hands-on | D20: Day 4: watch 3Blue1Brown NN videos ch. 1-3 | E20: But what IS a Neural Network?', 'Gradient descent', 'What does backpropagation really do?'. ~60 min total. Watch, don't pause to implement. | F20: Visual intuition for what's inside the model box. Watching is enough; implementing is for later if at all. | G20: Intern | H20: Done
A21: Week 0 | B21: =IF(ISNUMBER(Overview!B6),Overview!B6+0,"") | C21: Hands-on | D21: Day 4: 1-page reflection in own words | E21: Answer in his own words: 'What is a neural network? What does training mean? Why do we need data?' One page max. | F21: Watching != understanding. Writing in own words tests retention and exposes gaps cheaply. THIS is the bootstrap diagnostic. | G21: Intern | H21: Done
A22: Week 0 | B22: =IF(ISNUMBER(Overview!B6),Overview!B6+0,"") | C22: Concept | D22: Day 4: attention/transformers - 1-page primer | E22: Single page only: transformers are a NN architecture good at sequences. Attention lets each token 'look at' other tokens. Read Jay Alammar 'Illustrated Transformer' intro (first 1/3 only). | F22: One-page bird's-eye view so transformer vocabulary in Weeks 2-5 isn't entirely foreign. Don't go deep. | G22: Intern | H22: Done
A23: Week 0 | B23: =IF(ISNUMBER(Overview!B6),Overview!B6+0,"") | C23: Hands-on | D23: Day 5: first PyTorch tensor | E23: pip install torch. torch.tensor([1,2,3]). Move .to('cuda'). Print .shape, .dtype, .device. Matmul of two random 1000x1000 tensors on CPU vs GPU, time both. | F23: Tactile first PyTorch experience. CPU-vs-GPU timing makes the Day-3 'why GPU' concept concrete. | G23: Intern | H23: Done | I23: https://github.com/makarkul/bharatgen-speech-intern-2026/tree/claude/setup-intern-project-FkRbX/week0/day5_pytorch_tensors.ipynb | J23: torch.tensor created, moved to/from cuda; .shape/.dtype/.device printed
A24: Week 0 | B24: =IF(ISNUMBER(Overview!B6),Overview!B6+0,"") | C24: Hands-on | D24: Day 5: run HF distilbert via pipeline() | E24: from transformers import pipeline; pipe = pipeline('sentiment-analysis'); pipe('I love this'). Three lines. Print the output. | F24: Easiest possible HF entry. No AutoModel/AutoTokenizer yet — just see that 'model goes brrr' works. | G24: Intern | H24: Done | I24: https://github.com/makarkul/bharatgen-speech-intern-2026/tree/claude/setup-intern-project-FkRbX/week0/day5_pytorch_tensors.ipynb | J24: pipeline('sentiment-analysis') run on 2 sentences with prose explanation of the load/tokenize/inference flow
A25: Week 0 | B25: =IF(ISNUMBER(Overview!B6),Overview!B6+0,"") | C25: Hands-on | D25: Day 5: first commit | E25: Commit week0_bootstrap.ipynb to repo with all Day 1-5 exercises. First git push. | F25: Repo hygiene begins. Friday review now has something to review. | G25: Intern | H25: Done | I25: https://github.com/makarkul/bharatgen-speech-intern-2026/tree/claude/setup-intern-project-FkRbX | J25: Multiple commits to claude/setup-intern-project-FkRbX; week0_bootstrap.ipynb + day notebooks pushed
A26: Week 0 | B26: =IF(ISNUMBER(Overview!B6),Overview!B6+0,"") | C26: Deliverable | D26: week0_bootstrap.ipynb + reflection.md | E26: Single notebook covering Days 1-5 exercises. reflection.md = his 1-page NN explanation from Day 4. | F26: Single artifact for the week. Reviewable in one sitting. Reflection.md is the diagnostic — if vague, slow Week 1 down. | G26: Intern | H26: Done | I26: https://github.com/makarkul/bharatgen-speech-intern-2026/tree/claude/setup-intern-project-FkRbX/week0 | J26: Per-day notebooks (day1_numpy, day2_matplotlib_librosa, day3_ml_tokens_tensor, day5_pytorch_tensors) + reflection.md (NN, training, attention/transformers) committed. Intern split the single bootstrap notebook by day; deliverable spec accepted as 'Done'.
A27: Week 0 | B27: =IF(ISNUMBER(Overview!B6),Overview!B6+0,"") | C27: Anti-pattern | D27: Don't: implement a NN from scratch | E27: Skip 'build your own neural network in numpy' tutorials. Skip backprop derivations. | F27: Optimization target for Week 0 is conceptual coverage, not building. Implementation is a Week-9+ activity (i.e., after this internship). | G27: Intern | H27: Done | J27: No scratch-NN implementation in week0 notebooks
A28: Week 0 | B28: =IF(ISNUMBER(Overview!B6),Overview!B6+0,"") | C28: Anti-pattern | D28: Don't: read PyTorch tutorials past 'Tensors' | E28: Skip 'Autograd', 'Training a Classifier', 'Optimization'. Those are training-stack content; we don't train. | F28: Inference-only scope. Reading training content now muddles the mental model. | G28: Intern | H28: Done | J28: Day 5 stayed at tensor creation + device moves; no autograd
A29: Week 0 | B29: =IF(ISNUMBER(Overview!B6),Overview!B6+0,"") | C29: Anti-pattern | D29: Don't: stress over 3Blue1Brown math | E29: If gradient descent algebra is hard, that's fine. Watch for intuition; math doesn't gate Week 1. | F29: Math fluency is not a Week-0 prerequisite. Sets expectations. | G29: Intern | H29: Done | J29: Reflection captures intuition without algebra
A30: Week 1 | B30: =IF(ISNUMBER(Overview!B6),Overview!B6+7,"") | C30: Concept | D30: Sampling rate: 16 kHz vs 44.1 kHz | E30: What sampling rate means; why ASR models specify 16 kHz; what happens when you pass 44.1 kHz to a 16 kHz model. | F30: Sample-rate mismatch is a top silent-failure mode. Spot it now, save 4 hours of debugging later. | G30: Intern | H30: Done
A31: Week 1 | B31: =IF(ISNUMBER(Overview!B6),Overview!B6+7,"") | C31: Concept | D31: Mono vs stereo | E31: Why speech models expect mono. How to convert stereo to mono in librosa/torchaudio. | F31: Common preprocessing bug source. | G31: Intern | H31: Done
A32: Week 1 | B32: =IF(ISNUMBER(Overview!B6),Overview!B6+7,"") | C32: Concept | D32: Waveform vs spectrogram, mel scale | E32: Visual difference; what models actually consume; why mel rather than linear frequency. | F32: Models consume spectrograms, humans see waveforms. Bridging this gap visually = fastest path to intuition. | G32: Intern | H32: Done | I32: https://github.com/makarkul/bharatgen-speech-intern-2026/blob/claude/setup-intern-project-FkRbX/week1/week1_audio_basics.ipynb | J32: Covered in week1_audio_basics.ipynb + mel-spec plots for 5 languages
A33: Week 1 | B33: =IF(ISNUMBER(Overview!B6),Overview!B6+7,"") | C33: Concept | D33: Tensor basics in practice | E33: tensor.to(device), .shape, .dtype, .cpu(), .numpy(). Why device-mismatched ops fail. | F33: Builds on Week 0 Day 5 with more depth now that bootstrap context exists. | G33: Intern | H33: Done | I33: https://github.com/makarkul/bharatgen-speech-intern-2026/blob/claude/setup-intern-project-FkRbX/week1/week1_tensors_matmul.ipynb | J33: .shape/.dtype/.device/.to()/.numpy() walked through with examples
A34: Week 1 | B34: =IF(ISNUMBER(Overview!B6),Overview!B6+7,"") | C34: Hands-on | D34: Record 5 clips in different languages | E34: Phone recordings: Hindi, English, plus 3 of Marathi/Tamil/Kannada/Bengali. Save as WAV. | F34: Real audio surfaces real preprocessing issues that synthetic test files don't. | G34: Intern | H34: Done | I34: https://github.com/makarkul/bharatgen-speech-intern-2026/tree/claude/setup-intern-project-FkRbX/week1/data/audio_clips | J34: 5 .wav clips committed: English, Hindi, Kannada, Marathi, Telugu
A35: Week 1 | B35: =IF(ISNUMBER(Overview!B6),Overview!B6+7,"") | C35: Hands-on | D35: Plot waveform and mel-spectrogram | E35: Side-by-side plots in librosa. Zoom in on silence vs speech. Annotate which is which. | F35: Visualization grounds the abstract. Annotation forces him to articulate what he sees. | G35: Intern | H35: Done | I35: https://github.com/makarkul/bharatgen-speech-intern-2026/tree/claude/setup-intern-project-FkRbX/week1/data/plots | J35: Side-by-side waveform + mel-spectrogram PNGs for all 5 language clips
A36: Week 1 | B36: =IF(ISNUMBER(Overview!B6),Overview!B6+7,"") | C36: Hands-on | D36: Resample 44.1 -> 16 kHz, listen to both | E36: torchaudio.transforms.Resample. Listen and compare. Note what's lost. | F36: Demonstrates that significant information loss is tolerable for intelligibility — frames why ASR standardized on 16 kHz. | G36: Intern | H36: Done | I36: https://github.com/makarkul/bharatgen-speech-intern-2026/blob/claude/setup-intern-project-FkRbX/week1/resampling_16khz.ipynb | J36: 48kHz->16kHz torchaudio resample with subjective listen-comparison notes
A37: Week 1 | B37: =IF(ISNUMBER(Overview!B6),Overview!B6+7,"") | C37: Hands-on | D37: Time CPU vs GPU matmul (larger) | E37: 10000x10000 matmul, CPU vs GPU. Compare to Week 0 Day 5's 1000x1000 numbers. | F37: Quantifies how the gap grows with size. Concrete intuition for batching benefits later. | G37: Intern | H37: Done | I37: https://github.com/makarkul/bharatgen-speech-intern-2026/blob/claude/setup-intern-project-FkRbX/week1/week1_tensors_matmul.ipynb | J37: Benchmarks at 1000/2500/10000 matrix sizes, CPU vs GPU with synchronize()
A38: Week 1 | B38: =IF(ISNUMBER(Overview!B6),Overview!B6+7,"") | C38: Deliverable | D38: week1_audio_basics.ipynb + audio_cheatsheet.md | E38: Notebook with plots and annotations. 1-page cheatsheet: sampling rate, mono/stereo, resampling, mel-spectrogram. | F38: Cheatsheet seeds the handoff package. Audience-of-two forces clarity. | G38: Intern | H38: Done | I38: https://github.com/makarkul/bharatgen-speech-intern-2026/tree/claude/setup-intern-project-FkRbX/week1 | J38: Both deliverable files present: week1_audio_basics.ipynb and audio_cheatsheet.md
A39: Week 1 | B39: =IF(ISNUMBER(Overview!B6),Overview!B6+7,"") | C39: Anti-pattern | D39: Don't: read Stanford CS224S lectures | E39: Skip the full course. Theory rabbit hole. | F39: Three weeks can disappear into lectures with no code shipped. | G39: Intern | H39: Done | J39: No detour into CS224S — stayed on librosa/torchaudio primitives
A40: Week 1 | B40: =IF(ISNUMBER(Overview!B6),Overview!B6+7,"") | C40: Anti-pattern | D40: Don't: derive Fourier transforms | E40: Pattern-match what librosa produces. Don't reinvent the FFT. | F40: Not on the critical path to running BharatGen models. | G40: Intern | H40: Done | J40: Used librosa/torch primitives directly; no FFT re-derivation
...

Sheet Glossary
A1: Glossary
A2: One-line definitions for every ML / audio / inference term used in the plan. Aimed at someone who's just finished Week 0. Use as a lookup, not as study material.
A4: Category | B4: Term | C4: Plain-English definition | D4: First appears
A5: Audio | B5: Sampling rate | C5: How many audio measurements are taken per second. 16,000/sec (16 kHz) is the speech-model standard; CD audio is 44,100/sec. | D5: Week 1
A6: Audio | B6: Waveform | C6: The raw audio signal as a 1-D array of amplitude values over time. What you see in Audacity. | D6: Week 1
A7: Audio | B7: Spectrogram | C7: A 2-D image showing how energy at different frequencies changes over time. Models eat this, not the raw waveform. | D7: Week 1
A8: Audio | B8: Mel-spectrogram | C8: A spectrogram with frequencies rescaled to the mel scale (closer to how humans hear). Standard input for speech models. | D8: Week 1
A9: Audio | B9: Mono / Stereo | C9: Mono = 1 channel. Stereo = 2 channels. Speech models almost always want mono. | D9: Week 1
A10: PyTorch | B10: Tensor | C10: An n-dimensional array of numbers (like a numpy array) that can live on a GPU and support gradient tracking. For our purposes: numpy array on a graphics card. | D10: Week 0
A11: PyTorch | B11: Device | C11: Where a tensor lives: 'cpu' or 'cuda' (GPU). Operations between tensors on different devices fail. | D11: Week 0
A12: PyTorch | B12: dtype | C12: The numeric type of tensor elements: float32 (default), float16, bfloat16, int8, etc. Affects memory and precision. | D12: Week 0
A13: PyTorch | B13: Broadcasting | C13: Rules that let operations between tensors of different shapes work (e.g., adding (3,1) and (1,4) produces (3,4)). | D13: Week 0
A14: PyTorch | B14: torch.no_grad() | C14: A context manager that turns off gradient tracking. Use during inference: halves memory, speeds up. | D14: Week 2
A15: PyTorch | B15: model.eval() | C15: Switches a model from training mode to inference mode. Affects layers like dropout and batchnorm. | D15: Week 2
... A54: Engineering | B54: Peak GPU memory | C54: The maximum GPU memory used during an operation. Measured with torch.cuda.max_memory_allocated(). | D54: Week 3

Sheet Deliverables
A1: Week | B1: Deliverable | C1: Description | D1: Why it matters | E1: Status | F1: Evidence / Link
A2: Week 0 | B2: week0_bootstrap.ipynb + reflection.md | C2: Notebook covering numpy, matplotlib, first PyTorch tensor, first HF pipeline() call. reflection.md = 1-page 'what is a NN' in his own words. | D2: Diagnostic for whether bootstrap landed. Vague reflection -> slow Week 1 down. | E2: Done | F2: https://github.com/makarkul/bharatgen-speech-intern-2026/tree/claude/setup-intern-project-FkRbX/week0
A3: Week 1 | B3: week1_audio_basics.ipynb + audio_cheatsheet.md | C3: Audio plots + 1-page cheatsheet on sampling rate, mono/stereo, resampling, mel-spectrogram. | D3: Cheatsheet seeds the handoff package. | E3: Done | F3: https://github.com/makarkul/bharatgen-speech-intern-2026/tree/claude/setup-intern-project-FkRbX/week1
A4: Week 2 | B4: how_to_run_an_hf_model.md | C4: Tutorial: AutoModel/Tokenizer/Processor, cache, eval mode, no_grad. Code + screenshots. | D4: Writing-for-others test of understanding. | E4: Not Started
A5: Week 3 | B5: week3_shrutam2_eval.md | C5: WER table (Shrutam-2 vs Whisper, per language), profiling table, 5 failure cases with hypotheses. | D5: First quantitative comparison. Establishes the rigor bar. | E5: Not Started
A6: Week 4 | B6: week4_sooktam2_eval.md + audio samples | C6: Markdown + audio. Indic Parler comparison. Edge-case failures documented. | D6: Quality claims backed by listenable artifacts. | E6: Not Started
A7: Week 5 | B7: week5_indictrans2_eval.md + translate.py CLI | C7: Translation eval + reusable CLI consumed by Week 6 pipeline. | D7: First reusable artifact. | E7: Not Started
A8: Week 6 | B8: Gradio demo + architecture.md | C8: Click-through STT -> Translate -> TTS demo. Hand-drawn architecture diagram with memory budget and failure modes. | D8: The actual goal. Drawing tests understanding. | E8: Not Started
A9: Week 7 | B9: Tagged repo v1.0-intern-handoff | C9: Complete handoff: README, SETUP, EXPERIMENTS, NEXT_STEPS, LIMITATIONS, 30-min Loom. | D9: Next intern starts at Week 6, not Week 0. | E9: Not Started

Sheet Cadence
A1: When | B1: Activity | C1: Duration | D1: Format | E1: Owner | F1: Rationale
A2: Monday morning | B2: Intern posts the week's plan | C2: 15 min | D2: Async (Slack) | E2: Intern | F2: Forces intent-setting before the week starts. Monday corrections are cheap; mid-week corrections cost a day.
A3: Wednesday | B3: Blocker check (optional) | C3: 10 min | D3: Slack or call | E3: Either | F3: Mid-week safety net. Skip if not blocked. Prevents 'silently stuck Tue-Thu' pattern.
A4: Friday EOD | B4: Commit week's deliverable + 5-bullet progress note | C4: Async | D4: Git + Slack | E4: Intern | F4: Forced reflection. The 5 bullets become EXPERIMENTS.md timeline in Week 7.
A5: Friday next day | B5: Mentor reviews commits | C5: 30 min | D5: GitHub PR comments | E5: Mentor | F5: Async review. Schedules any Monday correction.
A6: End of each week | B6: Update Tracker status + evidence links | C6: 5 min | D6: This spreadsheet | E6: Intern | F6: Single source of truth for progress.
A7: End of Week 0 | B7: Mentor reads intern's reflection.md | C7: 10 min | D7: GitHub | E7: Mentor | F7: Bootstrap diagnostic. Vague reflection -> slow Week 1. Specific reflection -> proceed at planned pace.

Sheet Success Criteria
A1: Week-7 Success Questions
A2: If the intern can answer these without hedging at the end of Week 7, the plan worked.
A4: # | B4: Question | C4: What a good answer looks like | D4: Intern's answer (Week 7)
A5: 1 | B5: For a 10-second Hindi audio file end-to-end translated to English speech, where does the time actually go? Give it to me in milliseconds per stage. | C5: Stage-by-stage breakdown: ASR ms, translation ms, TTS ms, overhead/copies ms, total ms. Hardware noted. Points at the dominant stage and explains why.
A6: 2 | B6: Why can't we run all three models on a 16 GB GPU simultaneously without something giving? | C6: Numbers: per-model peak GPU memory. Aggregate. Names the dominant consumer. Discusses fp16/bf16, offload, lazy load as mitigations.
A7: 3 | B7: What's the difference between how Shrutam-2 and Whisper handle code-mixed Hindi-English, based on your measurements? | C7: WER numbers on the same code-mixed test set. Qualitative observation: where each tokenizer breaks. Speculation about training-data distribution.
A8: 4 | B8: Sooktam-2 is reference-guided. What does that mean for output quality, and what does it mean for inference latency compared to a description-conditioned model like Indic Parler-TTS? | C8: Quality: bounded by reference clip quality. Latency: extra reference encoding pass, RTF numbers for both. Trade-off articulated.
A9: 5 | B9: If I gave you a 30-minute audio file, what breaks and why? | C9: Memory growth (KV cache or buffer). Context limits. Chunking strategy needed. Error compounding across chunks for translation stage.

Sheet Anti-Patterns
A1: Week | B1: Don't do this | C1: Why it's tempting | D1: Why to avoid
A2: Week 0 | B2: Implementing a neural network from scratch in numpy | C2: Feels like 'doing prerequisites properly'. | D2: Week 0 is conceptual coverage, not building. Implementation can be a post-internship project.
A3: Week 0 | B3: Reading PyTorch tutorials past 'Tensors' | C3: PyTorch.org's tutorials look authoritative. | D3: Autograd / training tutorials are training-stack content. We don't train; reading them muddles the model.
A4: Week 0 | B4: Stressing over 3Blue1Brown's math | C4: Math fluency feels prerequisite. | D4: Watch for intuition, not algebra. Math doesn't gate Week 1.
A5: Week 1 | B5: Reading Stanford CS224S lectures front-to-back | C5: Feels like 'doing prerequisites properly'. | D5: Three weeks disappear into lectures with zero code shipped.
A6: Week 1 | B6: Trying to derive Fourier transforms before plotting one | C6: First-principles instinct. | D6: FFT math is not on the critical path to running BharatGen models.
A7: Week 2 | B7: Fine-tuning anything (LoRA, full, PEFT) | C7: Most-talked-about thing in ML. | D7: Half-trained checkpoints with no documentation. Inference depth > training breadth here.
A8: Week 2 | B8: Pulling in accelerate / bitsandbytes / vLLM | C8: Sounds professional. | D8: Adds debugging surface without solving a current problem.
A9: Week 3 | B9: Trying to 'improve' Shrutam-2 | C9: WER is bad on some clips - instinct is to fix it. | D9: Improvement is meaningless before measurement is solid.
A10: Week 3 | B10: Reporting numbers without hardware/batch context | C10: Easy oversight in a hurry. | D10: A number without context is noise.
A11: Week 4 | B11: Claiming TTS quality without samples | C11: 'Sounds good' feels honest. | D11: Untestable claims become folk wisdom.
A12: Week 4 | B12: Blaming the model when the reference clip is bad | C12: Garbage in is harder to spot than garbage out. | D12: Wastes weeks debugging the wrong thing.
... A16: Week 7 | B16: Leaving docs for the last day | C16: Always tempting. | D16: Doc-only-in-week-7 misses ~30% of what was done.

Sheet Learning Resources
A1: Learning Resources
A2: Specific, named resources for each week's concepts. Curated, not exhaustive. Primary = required. Supplementary = if interested or stuck.
A4: Phase | B4: Topic | C4: Priority | D4: Resource | E4: Type | F4: Time | G4: URL
A5: Pre-start | B5: RunPod basics | C5: Primary | D5: RunPod Pods Overview + Quickstart | E5: Docs | F5: 30 min | G5: https://docs.runpod.io/pods/overview
A6: Pre-start | B6: BharatGen context | C6: Primary | D6: AI4Bharat blog (skim IndicASR/IndicTTS posts) | E6: Blog | F6: 1 hour | G6: https://ai4bharat.iitm.ac.in/blog
A7: Week 0 Day 1 | B7: numpy | C7: Primary | D7: SciPy Lectures: NumPy | E7: Course | F7: 2 hours | G7: https://lectures.scientific-python.org/intro/numpy/index.html
A8: Week 0 Day 1 | B8: numpy | C8: Supplementary | D8: NumPy Absolute Beginners guide | E8: Docs | F8: 45 min | G8: https://numpy.org/doc/stable/user/absolute_beginners.html
A9: Week 0 Day 1 | B9: Jupyter | C9: Primary | D9: Real Python: Jupyter Notebook Introduction | E9: Article | F9: 30 min | G9: https://realpython.com/jupyter-notebook-introduction/
A10: Week 0 Day 1 | B10: venv / uv | C10: Primary | D10: Astral uv: Getting Started | E10: Docs | F10: 20 min | G10: https://docs.astral.sh/uv/getting-started/
A11: Week 0 Day 2 | B11: matplotlib | C11: Primary | D11: Matplotlib: Pyplot tutorial | E11: Docs | F11: 45 min | G11: https://matplotlib.org/stable/tutorials/pyplot.html
A12: Week 0 Day 2 | B12: librosa (reading practice) | C12: Primary | D12: librosa: Tutorial | E12: Docs | F12: 1 hour | G12: https://librosa.org/doc/latest/tutorial.html
A13: Week 0 Day 3 | B13: What is a 'model' | C13: Primary | D13: Stephen Wolfram: What Is ChatGPT Doing? (first third only — through 'Inside ChatGPT') | E13: Essay | F13: 1.5 hours | G13: https://writings.stephenwolfram.com/2023/02/what-is-chatgpt-doing-and-why-does-it-work/
A14: Week 0 Day 3 | B14: Tokenizer concept | C14: Primary | D14: HF Tokenizers: Summary | E14: Docs | F14: 20 min | G14: https://huggingface.co/docs/transformers/tokenizer_summary
A15: Week 0 Day 3 | B15: GPU vs CPU | C15: Primary | D15: NVIDIA blog: CPU vs GPU | E15: Article | F15: 15 min | G15: https://blogs.nvidia.com/blog/whats-the-difference-between-a-cpu-and-a-gpu/
... A36: Week 7 | B36: Technical writing structure | C36: Primary | D36: Diátaxis framework (4 doc types: tutorials, how-tos, reference, explanations) | E36: Reading | F36: 30 min | G36: https://diataxis.fr/
